Workbook

Sheet Caso 1
A1: A continuación se presentan los Estados Financieros para Amazon en 2014 y 2015
A2: Evalue la liquidez y solvencia de la compañía durante el 2015, respondiendo a las siguientes preguntas.
A3: 1 | B3: ¿Cree que la compañía incumplirá con sus compromisos de corto plazo?
A4: 2 | B4: ¿Qué razones y qué criterio utilizaría para fundamentar su respuesta?
A5: 3 | B5: ¿Cree que la compañía incumplirá con sus compromisos de largo plazo?
A6: 4 | B6: ¿Qué razón/es y qué crierio utilizaría para fundamentar su respuesta?
A11: Consolidated Balance Sheet
A12: At December 31, 2015
A13: In Millions
C14: Crec. | D14: % | E14: 2015 | F14: 2014 | I14: Crec. | J14: % | K14: 2015 | L14: 2014
B15: Current assets | H15: Current liabilities
B16: Inventories | C16: =E16/F16-1 -> 0.23424509 | D16: =E16/$E$28 -> 0.15651549 | E16: 10243 | F16: 8299 | H16: Accounts payable | I16: =K16/L16-1 -> 0.23926119 | J16: =K16/$E$28 -> 0.31167105 | K16: 20397 | L16: 16459
B17: Account receivables, net | C17: =E17/F17-1 -> 0.14451176 | D17: =E17/$E$28 -> 0.098144979 | E17: 6423 | F17: 5612 | H17: Accrued expenses and other liabilites | I17: =K17/L17-1 -> 0.058835526 | J17: =K17/$E$28 -> 0.15867001 | K17: 10384 | L17: 9807
B18: Marketable securities | C18: =E18/F18-1 -> 0.37040923 | D18: =E18/$E$28 -> 0.059867979 | E18: 3918 | F18: 2859 | H18: Unearned revenue | I18: =K18/L18-1 -> 0.71036753 | J18: =K18/$E$28 -> 0.047643787 | K18: 3118 | L18: 1823
B19: Cash and cash equivalents | C19: =E19/F19-1 -> 0.091571065 | D19: =E19/$E$28 -> 0.24280301 | E19: 15890 | F19: 14557 | H19: Total current liabilites | I19: =K19/L19-1 -> 0.20684254 | J19: =K19/$E$28 -> 0.51798484 | K19: =SUM(K16:K18) -> 33899 | L19: =SUM(L16:L18) -> 28089
B20: Total current assets | C20: =E20/F20-1 -> 0.16429917 | D20: =E20/$E$28 -> 0.55733146 | E20: =SUM(E16:E19) -> 36474 | F20: =SUM(F16:F19) -> 31327
H21: Non-current liabilites
B22: Non current assets | H22: Long term debt | I22: =K22/L22-1 -> -0.0036297641 | J22: =K22/$E$28 -> 0.12583277 | K22: 8235 | L22: 8265
B23: Property, plant & equipment, net | C23: =E23/F23-1 -> 0.2870867 | D23: =E23/$E$28 -> 0.33368987 | E23: 21838 | F23: 16967 | H23: Other long term liabilities | I23: =K23/L23-1 -> 0.33954116 | J23: =K23/$E$28 -> 0.15167166 | K23: 9926 | L23: 7410
B24: Goodwill | C24: =E24/F24-1 -> 0.13257005 | D24: =E24/$E$28 -> 0.057438421 | E24: 3759 | F24: 3319 | H24: Total non-current liabilities | I24: =K24/L24-1 -> 0.15859649 | J24: =K24/$E$28 -> 0.27750443 | K24: =SUM(K22:K23) -> 18161 | L24: =SUM(L22:L23) -> 15675
B25: Other assets | C25: =E25/F25-1 -> 0.16632089 | D25: =E25/$E$28 -> 0.051540248 | E25: 3373 | F25: 2892 | H25: Total liabilities | I25: =K25/L25-1 -> 0.1895622 | J25: =K25/$E$28 -> 0.79548927 | K25: =K19+K24 -> 52060 | L25: =L19+L24 -> 43764
B26: Total non current assets | C26: =E26/F26-1 -> 0.24989214 | D26: =E26/$E$28 -> 0.44266854 | E26: =SUM(E23:E25) -> 28970 | F26: =SUM(F23:F25) -> 23178 | H26: Shareholders' equity
H27: Common stock and paid in capital | I27: =K27/L27-1 -> 0.20278276 | J27: =K27/$E$28 -> 0.20473993 | K27: 13399 | L27: 11140
B28: Total assets | C28: =E28/F28-1 -> 0.20069718 | D28: =E28/$E$28 -> 1 | E28: =SUM(E26,E20) -> 65444 | F28: =SUM(F26,F20) -> 54505 | H28: Treasury stock | I28: =K28/L28-1 -> 0 | J28: =K28/$E$28 -> -0.0280698 | K28: -1837 | L28: -1837
H29: Accumulated other comprehensive loss | I29: =K29/L29-1 -> 0.4148728 | J29: =K29/$E$28 -> -0.011047613 | K29: -723 | L29: -511
H30: Retained earnings | I30: =K30/L30-1 -> 0.30579785 | J30: =K30/$E$28 -> 0.03888821 | K30: 2545 | L30: 1949
H31: Shareholders' equity | I31: =K31/L31-1 -> 0.24606647 | J31: =K31/$E$28 -> 0.20451073 | K31: =SUM(K27:K30) -> 13384 | L31: =SUM(L27:L30) -> 10741
H33: Total liabilites + equity | I33: =K33/L33-1 -> 0.20069718 | J33: =K33/$E$28 -> 1 | K33: =SUM(K19,K24,K31) -> 65444 | L33: =SUM(L19,L24,L31) -> 54505
G36: * | H36: Financial Leases | I36: 1736
H37: Capital Leases | I37: 4212
A38: Income Statement
A39: Year Ended December 31, 2015 | E39: 2015 | F39: 2014
B42: Net product sales | C42: =E42/F42-1 -> 0.13110731 | D42: =E42/$E$44 -> 0.74078089 | E42: 79268 | F42: 70080
B43: Net service sales | C43: =E43/F43-1 -> 0.4669981 | D43: =E43/$E$44 -> 0.25921911 | E43: 27738 | F43: 18908
B44: Total net sales | C44: =E44/F44-1 -> 0.20247674 | D44: =E44/$E$44 -> 1 | E44: =SUM(E42:E43) -> 107006 | F44: =SUM(F42:F43) -> 88988
B46: Operating expenses
B47: Cost of sales | C47: =E47/F47-1 -> 0.14181221 | D47: =E47/$E$44 -> 0.66959797 | E47: 71651 | F47: 62752
B48: Fulfillment | C48: =E48/F48-1 -> 0.24558796 | D48: =E48/$E$44 -> 0.12532008 | E48: 13410 | F48: 10766
B49: Marketing | C49: =E49/F49-1 -> 0.21283472 | D49: =E49/$E$44 -> 0.04910005 | E49: 5254 | F49: 4332
B50: Technology and content | C50: =E50/F50-1 -> 0.35202156 | D50: =E50/$E$44 -> 0.11718969 | E50: 12540 | F50: 9275
...

Sheet C1 (sol)
B3: LIQUIDEZ | C3: 2015
B5: Activo Circulante | C5: ='Caso 1'!E20 -> 36474 | D5: ='Caso 1'!F20 -> 31327
B6: Pasivo Circulante | C6: ='Caso 1'!K19 -> 33899 | D6: ='Caso 1'!L19 -> 28089
B7: Razón Liquidez | C7: =C5/C6 -> 1.0759609 | D7: =D5/D6 -> 1.1152764 | F7: Esta razón es suficiente, inventarios son líquidos (rotación es de 8x)
B9: Inventarios | C9: ='Caso 1'!E16 -> 10243 | D9: ='Caso 1'!F16 -> 8299
B11: Prueba Ácida | C11: =(C5-C9)/C6 -> 0.77379864 | D11: =(D5-D9)/D6 -> 0.81982271
B13: COMPLEMENTAMOS ANÁLISIS DE LIQUIDEZ CON ADM. DE ACTIVOS DE CP
B15: Costo de Ventas | C15: ='Caso 1'!E47 -> 71651
B16: Inventario Promedio | C16: =AVERAGE(C9:D9) -> 9271 | E16: ='Caso 1'!C16 -> 0.23424509 | F16: Inventarios tienen alto crecimiento de un año a otro, utilizamos promedio de año inicial y final para tener un mejor dato de referencia de saldo promedio del año.
B17: Rotación de inventario | C17: =C15/C16 -> 7.7285083
B19: Días al año | C19: 360
B20: Días Inventario | C20: =C19/C17 -> 46.580787
B22: Cuentas x Cobrar | C22: ='Caso 1'!E17 -> 6423 | D22: ='Caso 1'!F17 -> 5612
B23: Cuentas x Cobrar promedio | C23: =AVERAGE(C22:D22) -> 6017.5 | E23: ='Caso 1'!C17 -> 0.14451176 | F23: Utilizamos promedio de año inicial y final para tener un mejor dato de referencia de saldo promedio del año.
B24: Ventas | C24: ='Caso 1'!E44 -> 107006
B25: Ventas diarias | C25: =C24/C19 -> 297.23889
B26: Días CXC | C26: =C23/C25 -> 20.244659
B28: Cuentas x Pagar | C28: ='Caso 1'!K16 -> 20397 | D28: ='Caso 1'!L16 -> 16459
B29: Cuentas x Pagar promedio | C29: =AVERAGE(C28:D28) -> 18428 | E29: ='Caso 1'!I16 -> 0.23926119 | F29: Utilizamos el promedio de año inicial y final para tener un mejor dato de referencia de saldo promedio del año.
B30: Compras | C30: =H31 -> 73595 | F30: Inv. Inicial | G30: =D9 -> 8299 | N30: =C15 -> 71651
B31: Compras diarias | C31: =C30/C19 -> 204.43056 | F31: (+) Compras | G31: ? | H31: =G33-G30+G32 -> 73595 | N31: =N30/C19 -> 199.03056
B32: Días CXP | C32: =C29/C31 -> 90.14308 | F32: (-) COGS | G32: =C15 -> 71651 | N32: =C29/N31 -> 92.588798
F33: Inv. Final | G33: =C9 -> 10243
B34: Ciclo de conversión de efectivo | C34: =C20+C26-C32 -> -23.317634
B36: Días CXP (DPP) | C36: =C32 -> 90.14308
B37: Días Inv + Días CXC (DPC) | C37: =C20 -> 46.580787 | D37: =C26 -> 20.244659
B43: Flujo Operativo | C43: ='Caso 1'!E82 -> 11920
B45: Respuesta
A46: 1 | B46: No
A47: 2 | B47: A pesar de tener una razón circulante cerca de 1, no creo que la compañía incumpla con sus obligaciones de corto plazo porque su ciclo de efectivo es negativo (ellos obtienen su efectivo de las ventas incluso antes de tener que pagar).
B48: Razones utilizadas ( circulante, DPC, DI, DPP, ciclo de efectivo)
B51: SOLVENCIA
B53: Pasivos Totales | C53: ='Caso 1'!K25 -> 52060
B54: Activos Totales | C54: ='Caso 1'!E28 -> 65444
B55: Razón Endeudamiento | C55: =C53/C54 -> 0.79548927
B57: Deuda | C57: ='Caso 1'!K22+'Caso 1'!I36+'Caso 1'!I37 -> 14183 | F57: Por falta de mayor información para diferenciar a que se refieren con capital lease, para ser conservador, se toma todos los leases como parte de la deuda para el calculo de la razón
B58: Activos Totales | C58: =C54 -> 65444
B59: Razón Deuda | C59: =C57/C58 -> 0.21671964
B61: Deuda | C61: =C57 -> 14183
B62: Capital | C62: ='Caso 1'!K31 -> 13384
...

Sheet Caso 2
A1: 1 | B1: Realice un análisis de márgenes y responda las siguientes preguntas.
B2: a. ¿A qué se debe la caída en el márgen neto durante el 2013?
B3: b. ¿Cómo evaluaría el desempeño del área comercial para el manejo de precios? Asuma que la empresa vende un solo producto.
B4: c. ¿En qué año se tiene una tasa efectiva de impuesto menor?
B5: d. ¿Por qué será que incrementan los gastos por intereses durante el 2013?
E8: 2014 | F8: 2013 | G8: 2012
C9: Toneladas Métricas | E9: =F9*1.05 -> 11025 | F9: 10500 | G9: 10000
C10: Ventas | E10: 12127.5 | F10: 12075 | G10: 10000
C11: Costo de Ventas | E11: 5612.5 | F11: 6300 | G11: 4000
C12: Utilidad Bruta | E12: =E10-E11 -> 6515 | F12: =F10-F11 -> 5775 | G12: =G10-G11 -> 6000
C13: Gastos de Venta y Administrativos | E13: 2800 | F13: 2500 | G13: 3000
C14: Utilidad Operativa | E14: =E12-E13 -> 3715 | F14: =F12-F13 -> 3275 | G14: =G12-G13 -> 3000
C15: Intereses | E15: 300 | F15: 350 | G15: 250
C16: Utilidad antes impuestos | E16: =E14-E15 -> 3415 | F16: =F14-F15 -> 2925 | G16: =G14-G15 -> 2750
C17: Impuestos | E17: 703 | F17: 526.5 | G17: 550
C18: Utilidad Neta | E18: =E16-E17 -> 2712 | F18: =F16-F17 -> 2398.5 | G18: =G16-G17 -> 2200
C20: Depreciaciones & Amortizaciones Costo | E20: 600 | F20: 500 | G20: 500
C21: Depreciaciones & Amortizaciones Gasto | E21: 50 | F21: 50 | G21: 50

Sheet C2 (Sol)
A2: 1 | B2: Realice un análisis de márgenes y responda las siguientes preguntas.
B3: a. ¿A qué se debe la caída en el márgen neto durante el 2013?
B4: b. ¿Cómo evaluaría el desempeño del área comercial para el manejo de precios? Asuma que la empresa vende un solo producto.
B5: c. ¿En qué año se tiene una tasa efectiva de impuesto menor?
B6: d. ¿Por qué será que incrementan los gastos por intereses durante el 2013?
D9: 2014 | E9: 2013 | F9: 2012 | I9: 2014 | J9: 2013 | K9: 2012
B10: TM | C10: =D10/E10-1 -> 0.05 | D10: =E10*1.05 -> 11025 | E10: 10500 | F10: 10000 | G10: =E10/F10-1 -> 0.05
B11: Ventas | C11: =D11/E11-1 -> 0.0043478261 | D11: 12127.5 | E11: 12075 | F11: 10000 | G11: =E11/F11-1 -> 0.2075
B12: Costo de Ventas | C12: =D12/E12-1 -> -0.10912698 | D12: 5612.5 | E12: 6300 | F12: 4000 | G12: =E12/F12-1 -> 0.575
B13: Utilidad Bruta | D13: =D11-D12 -> 6515 | E13: =E11-E12 -> 5775 | F13: =F11-F12 -> 6000 | H13: MARGEN Bruto | I13: =D13/D$11 -> 0.53720882 | J13: =E13/E$11 -> 0.47826087 | K13: =F13/F$11 -> 0.6 | L13: =J13-K13 -> -0.12173913
B14: Gastos de Venta y Administrativos | D14: 2800 | E14: 2500 | F14: 3000
B15: Utilidad Operativa | D15: =D13-D14 -> 3715 | E15: =E13-E14 -> 3275 | F15: =F13-F14 -> 3000 | H15: MARGEN Operativo | I15: =D15/D$11 -> 0.30632859 | J15: =E15/E$11 -> 0.27122153 | K15: =F15/F$11 -> 0.3
B16: Intereses | D16: 300 | E16: 350 | F16: 250
B17: Utilidad antes impuestos | D17: =D15-D16 -> 3415 | E17: =E15-E16 -> 2925 | F17: =F15-F16 -> 2750
B18: Impuestos | D18: 703 | E18: 526.5 | F18: 550 | H18: Tasa efectiva de impuesto | I18: =D18/D17 -> 0.20585652 | J18: =E18/E17 -> 0.18 | K18: =F18/F17 -> 0.2
B19: Utilidad Neta | D19: =D17-D18 -> 2712 | E19: =E17-E18 -> 2398.5 | F19: =F17-F18 -> 2200 | H19: MARGEN Neto | I19: =D19/D$11 -> 0.223624 | J19: =E19/E$11 -> 0.19863354 | K19: =F19/F$11 -> 0.22
B21: Depreciaciones & Amortizaciones Costo | D21: 600 | E21: 500 | F21: 500
B22: Depreciaciones & Amortizaciones Gasto | D22: 50 | E22: 50 | F22: 50
B23: EBITDA | D23: =D15+D21+D22 -> 4365 | E23: =E15+E21+E22 -> 3825 | F23: =F15+F21+F22 -> 3550 | H23: MARGEN EBITDA | I23: =D23/D11 -> 0.35992579 | J23: =E23/E11 -> 0.31677019 | K23: =F23/F11 -> 0.355
B25: Precio x unidad | C25: =D25/E25-1 -> -0.043478261 | D25: =D11/D10 -> 1.1 | E25: =E11/E10 -> 1.15 | F25: =F11/F10 -> 1 | G25: =E25/F25-1 -> 0.15
B26: Costo de ventas x unidad | C26: =D26/E26-1 -> -0.15154951 | D26: =D12/D10 -> 0.50907029 | E26: =E12/E10 -> 0.6 | F26: =F12/F10 -> 0.4 | G26: =E26/F26-1 -> 0.5
A28: a. | B28: La caída en el márgen neto se origina desde el márgen bruto. El costo de ventas incrementó.
A30: b. | B30: En 2013, el desempeño del área comercial no es óptimo. Las ventas en US$ crecen, pero en realidad no se logra trasladar todo el incremento en costos.
B31: Los costos x unidad crecen 50%, pero el precio x unidad solo se incrementa 15%, lo que origina una caída en el margen bruto de 12%.
B33: En el 2014, parece que el desempeño es mejor que en 2013, pues los costos bajan y los precios bajan en menor proporción, manteniendo un crecimiento en volumen de 5%.
B34: El margen bruto se eleva en 6% como resultado de esto.
A36: c. | B36: En el 2013.
A38: d. | B38: El incremento en costos tan alto, origina también un incremento en las cuentas de inventario y CxC.
B39: El alza en intereses posiblemente se deriva de que ese incremento en capital de trabajo se financia a través de una deuda mayor.

Sheet Caso 4
A1: 1 | B1: Asumiendo que no hay un cambio en otras variables, cuál de las siguientes reduciría el retorno sobre activos:
B2: a. Una reducción en la tasa efectiva de impuestos
B3: b. Una reducción de los gastos por intereses
B4: c. Un incremento en activos promedio
A6: 2 | B6: Con la información de la tabla, indique:
B7: a. ¿Cómo es la eficiencia en la administración de activos?
B8: b. Si el mercado en el que la empresa participa creció 10% en 2014, ¿Cómo calificaría el desempeño en ventas?
B9: c. Calcule el margen bruto e indique ¿a qué podría atribuirse su variación vs. el AA?
D11: 2014 | E11: 2013 | F11: 2012 | G11: 2011
B12: Días de inventario | D12: 35.555556 | E12: 40.666667 | F12: 40.5 | G12: 48.545455
B13: Días promedio de cobro | D13: 45.037037 | E13: 58.4 | F13: 51.3 | G13: 76.8
B14: Rotación de activos totales | D14: 0.36 | E14: 0.28 | F14: 0.23 | G14: 0.22
B15: Inventario promedio | D15: 780 | E15: 610 | F15: 495 | G15: 445
B16: Cuentas x Cobrar promedio | D16: 1520 | E16: 1460 | F16: 1140 | G16: 1280

Sheet C4 (Sol)
A1: 1 | B1: Asumiendo que no hay un cambio en otras variables, cuál de las siguientes reduciría el retorno sobre activos:
B2: a. Una reducción en la tasa efectiva de impuestos
B3: b. Una reducción de los gastos por intereses
B4: c. Un incremento en activos promedio
B7: ROA = Utilidad Neta/ Activos Totales
A9: c. | B9: El incremento en los activos totales indicaría que produzco la misma utilidad, pero requiero más recursos para lograrla, lo cual reduciría el retorno.
B10: a y b incrementarían el ROA, pues representarían un incremento a la utilidad neta.
A12: 2 | B12: Con la información de la tabla, indique:
B13: a. ¿Cómo es la eficiencia en la administración de activos?
B14: b. Si el mercado en el que la empresa participa creció 10% en 2014, ¿Cómo calificaría el desempeño en ventas?
B15: c. Calcule el margen bruto e indique ¿a qué podría atribuirse su variación vs. el AA?
D17: 2014 | E17: 2013 | F17: 2012 | G17: 2011
B18: Días de inventario | D18: 35.555556 | E18: 40.666667 | F18: 40.5 | G18: 48.545455
B19: Días promedio de cobro | D19: 45.037037 | E19: 58.4 | F19: 51.3 | G19: 76.8
B20: Rotación de activos totales | D20: 0.36 | E20: 0.28 | F20: 0.23 | G20: 0.22
B21: Inventario promedio | D21: 780 | E21: 610 | F21: 495 | G21: 445
B22: Cuentas x Cobrar promedio | D22: 1520 | E22: 1460 | F22: 1140 | G22: 1280
A34: a. | B34: La eficiencia en la administración de activos ha mejorado en los últimos años (Análisis histórico)
B35: Los dos indicadores disponibles de manejo de activos de corto plazo se reducen, lo que indica mayor eficiencia.
B36: El indicador de administración de activos de LP, indica que ésta es más eficiente.
B37: Para completar el análisis, sería necesario contar con datos de promedio de industria.
A39: b. | D39: 2014 | E39: 2013 | F39: 2012 | G39: 2011
B40: Ventas diarias | D40: =D22/D19 -> 33.75 | E40: =E22/E19 -> 25 | F40: =F22/F19 -> 22.222222 | G40: =G22/G19 -> 16.666667 | I40: PPC=CxC/Ventas x día
B41: Días al año | D41: 360 | E41: 360 | F41: 360 | G41: 360
B42: Ventas anuales | D42: =D40*D41 -> 12150 | E42: =E40*E41 -> 9000 | F42: =F40*F41 -> 8000 | G42: =G40*G41 -> 6000
B43: Crecimiento en ventas | D43: =D42/E42-1 -> 0.35 | E43: =E42/F42-1 -> 0.125 | F43: =F42/G42-1 -> 0.33333333
B45: La empresa tuvo un buen desempeño en ventas durante el 2014, pues creció por arriba del crecimiento del mercado.
B46: Probablemente logró un incremento fuerte en su participación de mercado.
A48: c. | D48: 2014 | E48: 2013 | F48: 2012 | G48: 2011 | I48: Rotación de inv. = Costo de ventas/Inventario
B49: Rotación de inventario | D49: =D41/D18 -> 10.125 | E49: =E41/E18 -> 8.852459 | F49: =F41/F18 -> 8.8888889 | G49: =G41/G18 -> 7.4157303 | I49: Días inv. = 360/Rotación de inv.
B50: Costo de Ventas | D50: =D49*D21 -> 7897.5 | E50: =E49*E21 -> 5400 | F50: =F49*F21 -> 4400 | G50: =G49*G21 -> 3300 | I50: Días de inv. = 360/(Costo de Ventas/Inventario)
B51: Utilidad Bruta | D51: =D42-D50 -> 4252.5 | E51: =E42-E50 -> 3600 | F51: =F42-F50 -> 3600 | G51: =G42-G50 -> 2700 | I51: ó
B52: Margen Bruto | D52: =D51/D42 -> 0.35 | E52: =E51/E42 -> 0.4 | F52: =F51/F42 -> 0.45 | G52: =G51/G42 -> 0.45 | I52: Días de inv. = Inventario / Costo de Ventas x día
B54: El márgen bruto se reduce, podría deberse a mayores costos, menores precios por unidad o venta de productos de menor márgen.
